<mujoco model="ant">
  <!-- dm_control assets -->
  <include file="common/skybox.xml"/>
  <include file="common/visual.xml"/>
  <include file="common/materials.xml"/>
  <compiler angle="degree" coordinate="local" inertiafromgeom="true"/>
  <!-- solver settings for MJX -->
  <option iterations="1" ls_iterations="4" timestep="0.01">
    <flag eulerdamp="disable"/>
  </option>
  <custom>
    <numeric data="0.0 0.0 0.55 1.0 0.0 0.0 0.0 0.0 1.0 0.0 -1.0 0.0 -1.0 0.0 1.0" name="init_qpos"/>
  </custom>
  <default>
    <joint armature="1" damping="1" limited="true"/>
    <geom contype="0" conaffinity="0"  condim="3" density="5.0" friction="1 0.5 0.5" margin="0.01" material="self"/>
  </default>
  <worldbody>
    <geom conaffinity="0" condim="3" material="grid" name="floor" pos="0 0 0" size="100 100 .5" type="plane"/>
    <body name="torso" pos="0 0 0.75">
      <camera name="track" mode="trackcom" pos="0 -3 0.3" xyaxes="1 0 0 0 0 1"/>
      <geom name="torso_geom" pos="0 0 0" size="0.25" type="sphere"/>
      <joint armature="0" damping="0" limited="false" margin="0.01" name="root" pos="0 0 0" type="free"/>
      <body name="front_left_leg" pos="0 0 0">
        <geom fromto="0.0 0.0 0.0 0.2 0.2 0.0" name="aux_1_geom" size="0.08" type="capsule"/>
        <body name="aux_1" pos="0.2 0.2 0">
          <joint axis="0 0 1" name="hip_1" pos="0.0 0.0 0.0" range="-30 30" type="hinge"/>
          <geom fromto="0.0 0.0 0.0 0.2 0.2 0.0" name="left_leg_geom" size="0.08" type="capsule"/>
          <body pos="0.2 0.2 0">
            <joint axis="-1 1 0" name="ankle_1" pos="0.0 0.0 0.0" range="30 70" type="hinge"/>
            <geom fromto="0.0 0.0 0.0 0.4 0.4 0.0" name="left_ankle_geom" size="0.08" type="capsule"/>
          </body>
        </body>
      </body>
      <body name="front_right_leg" pos="0 0 0">
        <geom fromto="0.0 0.0 0.0 -0.2 0.2 0.0" name="aux_2_geom" size="0.08" type="capsule"/>
        <body name="aux_2" pos="-0.2 0.2 0">
          <joint axis="0 0 1" name="hip_2" pos="0.0 0.0 0.0" range="-30 30" type="hinge"/>
          <geom fromto="0.0 0.0 0.0 -0.2 0.2 0.0" name="right_leg_geom" size="0.08" type="capsule"/>
          <body pos="-0.2 0.2 0">
            <joint axis="1 1 0" name="ankle_2" pos="0.0 0.0 0.0" range="-70 -30" type="hinge"/>
            <geom fromto="0.0 0.0 0.0 -0.4 0.4 0.0" name="right_ankle_geom" size="0.08" type="capsule"/>
          </body>
        </body>
      </body>
      <body name="back_leg" pos="0 0 0">
        <geom fromto="0.0 0.0 0.0 -0.2 -0.2 0.0" name="aux_3_geom" size="0.08" type="capsule"/>
        <body name="aux_3" pos="-0.2 -0.2 0">
          <joint axis="0 0 1" name="hip_3" pos="0.0 0.0 0.0" range="-30 30" type="hinge"/>
          <geom fromto="0.0 0.0 0.0 -0.2 -0.2 0.0" name="back_leg_geom" size="0.08" type="capsule"/>
          <body pos="-0.2 -0.2 0">
            <joint axis="-1 1 0" name="ankle_3" pos="0.0 0.0 0.0" range="-70 -30" type="hinge"/>
            <geom fromto="0.0 0.0 0.0 -0.4 -0.4 0.0" name="third_ankle_geom" size="0.08" type="capsule"/>
          </body>
        </body>
      </body>
      <body name="right_back_leg" pos="0 0 0">
        <geom fromto="0.0 0.0 0.0 0.2 -0.2 0.0" name="aux_4_geom" size="0.08" type="capsule"/>
        <body name="aux_4" pos="0.2 -0.2 0">
          <joint axis="0 0 1" name="hip_4" pos="0.0 0.0 0.0" range="-30 30" type="hinge"/>
          <geom fromto="0.0 0.0 0.0 0.2 -0.2 0.0" name="rightback_leg_geom" size="0.08" type="capsule"/>
          <body pos="0.2 -0.2 0">
            <joint axis="1 1 0" name="ankle_4" pos="0.0 0.0 0.0" range="30 70" type="hinge"/>
            <geom fromto="0.0 0.0 0.0 0.4 -0.4 0.0" name="fourth_ankle_geom" size="0.08" type="capsule"/>
          </body>
        </body>
      </body>
    </body>
  </worldbody>
  <actuator>
    <motor ctrllimited="true" ctrlrange="-1.0 1.0" joint="hip_4" gear="150"/>
    <motor ctrllimited="true" ctrlrange="-1.0 1.0" joint="ankle_4" gear="150"/>
    <motor ctrllimited="true" ctrlrange="-1.0 1.0" joint="hip_1" gear="150"/>
    <motor ctrllimited="true" ctrlrange="-1.0 1.0" joint="ankle_1" gear="150"/>
    <motor ctrllimited="true" ctrlrange="-1.0 1.0" joint="hip_2" gear="150"/>
    <motor ctrllimited="true" ctrlrange="-1.0 1.0" joint="ankle_2" gear="150"/>
    <motor ctrllimited="true" ctrlrange="-1.0 1.0" joint="hip_3" gear="150"/>
    <motor ctrllimited="true" ctrlrange="-1.0 1.0" joint="ankle_3" gear="150"/>
  </actuator>

  <!-- limits contacts for MJX -->
  <contact>
    <pair geom1="left_ankle_geom" geom2="floor"/>
    <pair geom1="right_ankle_geom" geom2="floor"/>
    <pair geom1="third_ankle_geom" geom2="floor"/>
    <pair geom1="fourth_ankle_geom" geom2="floor"/>
  </contact>
</mujoco>